{"uuid": "e8a79993-2e44-4d7b-89a6-0a7c0c2afdd0", "children": ["160cd42f-9293-4ccd-93ef-fde9df5ceddd"], "befores": [{"name": "login_pur", "status": "broken", "statusDetails": {"message": "selenium.common.exceptions.InvalidSessionIdException: Message: Tried to run command without establishing a connection\n\n", "trace": "  File \"c:\\programs\\python\\python36\\lib\\site-packages\\pluggy\\callers.py\", line 187, in _multicall\n    res = hook_impl.function(*args)\n  File \"c:\\programs\\python\\python36\\lib\\site-packages\\_pytest\\fixtures.py\", line 918, in pytest_fixture_setup\n    result = call_fixture_func(fixturefunc, request, kwargs)\n  File \"c:\\programs\\python\\python36\\lib\\site-packages\\_pytest\\fixtures.py\", line 778, in call_fixture_func\n    res = fixturefunc(**kwargs)\n  File \"C:\\gitStore\\test_zjc_pytest\\case\\zjc\\conftest.py\", line 6, in login_pur\n    login_page.pur_login(user,psw)\n  File \"C:\\gitStore\\test_zjc_pytest\\pageObject\\zjc\\loginPage.py\", line 29, in pur_login\n    self.open(zjc_login_url)\n  File \"C:\\gitStore\\test_zjc_pytest\\public\\basePage.py\", line 44, in open\n    self.driver.get(url)\n  File \"c:\\programs\\python\\python36\\lib\\site-packages\\selenium\\webdriver\\remote\\webdriver.py\", line 333, in get\n    self.execute(Command.GET, {'url': url})\n  File \"c:\\programs\\python\\python36\\lib\\site-packages\\selenium\\webdriver\\remote\\webdriver.py\", line 321, in execute\n    self.error_handler.check_response(response)\n  File \"c:\\programs\\python\\python36\\lib\\site-packages\\selenium\\webdriver\\remote\\errorhandler.py\", line 242, in check_response\n    raise exception_class(message, screen, stacktrace)\n"}, "start": 1566982813445, "stop": 1566982813446}], "start": 1566982813445, "stop": 1566982813600}