{"uuid": "3ae95e11-490f-4caa-acf9-80fb5c97021a", "children": ["846f6f33-248f-47a3-a07f-92da35d88b05"], "befores": [{"name": "login_cus", "status": "broken", "statusDetails": {"message": "selenium.common.exceptions.InvalidSessionIdException: Message: Tried to run command without establishing a connection\n\n", "trace": "  File \"c:\\programs\\python\\python36\\lib\\site-packages\\pluggy\\callers.py\", line 187, in _multicall\n    res = hook_impl.function(*args)\n  File \"c:\\programs\\python\\python36\\lib\\site-packages\\_pytest\\fixtures.py\", line 918, in pytest_fixture_setup\n    result = call_fixture_func(fixturefunc, request, kwargs)\n  File \"c:\\programs\\python\\python36\\lib\\site-packages\\_pytest\\fixtures.py\", line 778, in call_fixture_func\n    res = fixturefunc(**kwargs)\n  File \"C:\\gitStore\\test_zjc_pytest\\case\\zjc\\conftest.py\", line 14, in login_cus\n    login_page.custom_login(user,psw)\n  File \"C:\\gitStore\\test_zjc_pytest\\pageObject\\zjc\\loginPage.py\", line 45, in custom_login\n    self.open(custom_login_url)\n  File \"C:\\gitStore\\test_zjc_pytest\\public\\basePage.py\", line 44, in open\n    self.driver.get(url)\n  File \"c:\\programs\\python\\python36\\lib\\site-packages\\selenium\\webdriver\\remote\\webdriver.py\", line 333, in get\n    self.execute(Command.GET, {'url': url})\n  File \"c:\\programs\\python\\python36\\lib\\site-packages\\selenium\\webdriver\\remote\\webdriver.py\", line 321, in execute\n    self.error_handler.check_response(response)\n  File \"c:\\programs\\python\\python36\\lib\\site-packages\\selenium\\webdriver\\remote\\errorhandler.py\", line 242, in check_response\n    raise exception_class(message, screen, stacktrace)\n"}, "start": 1566982813352, "stop": 1566982813353}], "start": 1566982813352, "stop": 1566982813440}